<?xml version="1.0" encoding="utf-8"?>
<!-- This URDF was automatically created by SolidWorks to URDF Exporter! Originally created by Stephen Brawner (brawner@gmail.com) 
     Commit Version: 1.6.0-1-g15f4949  Build Version: 1.6.7594.29634
     For more information, please see http://wiki.ros.org/sw_urdf_exporter -->
<robot
  name="rUBotcoop_mecanum">
  <link
    name="base_link">
    <inertial>
      <origin
        xyz="0.027358779894703 -0.0197603692535836 -0.100882644576948"
        rpy="0 0 0" />
      <mass
        value="3.18539354368186" />
      <inertia
        ixx="0.0106842818448098"
        ixy="-5.63785129692462E-18"
        ixz="-7.33657587264312E-18"
        iyy="0.0166285557560687"
        iyz="-1.02898300437925E-07"
        izz="0.0271752644394761" />
    </inertial>
    <visual>
      <origin
        xyz="0 0 0"
        rpy="0 0 0" />
      <geometry>
        <mesh
          filename="package://rUBotcoop_mecanum/meshes/base_link.STL" />
      </geometry>
      <material
        name="">
        <color
          rgba="0.298039215686275 0.298039215686275 0.298039215686275 1" />
      </material>
    </visual>
    <collision>
      <origin
        xyz="0 0 0"
        rpy="0 0 0" />
      <geometry>
        <mesh
          filename="package://rUBotcoop_mecanum/meshes/base_link.STL" />
      </geometry>
    </collision>
  </link>
  <link
    name="Coberta_Link">
    <inertial>
      <origin
        xyz="-0.00415860178485479 -0.0197626395125796 -0.0410152049578553"
        rpy="0 0 0" />
      <mass
        value="4.68887274677187" />
      <inertia
        ixx="0.0779139499510574"
        ixy="-3.02761947211858E-07"
        ixz="0.00111949131598739"
        iyy="0.103102478258834"
        iyz="2.20300061116548E-07"
        izz="0.176660832697072" />
    </inertial>
    <visual>
      <origin
        xyz="0 0 0"
        rpy="0 0 0" />
      <geometry>
        <mesh
          filename="package://rUBotcoop_mecanum/meshes/Coberta_Link.STL" />
      </geometry>
      <material
        name="">
        <color
          rgba="0.498039215686275 0.498039215686275 0.498039215686275 1" />
      </material>
    </visual>
    <collision>
      <origin
        xyz="0 0 0"
        rpy="0 0 0" />
      <geometry>
        <mesh
          filename="package://rUBotcoop_mecanum/meshes/Coberta_Link.STL" />
      </geometry>
    </collision>
  </link>
  <joint
    name="joint_Coberta"
    type="fixed">
    <origin
      xyz="0 0 0"
      rpy="0 0 0" />
    <parent
      link="base_link" />
    <child
      link="Coberta_Link" />
    <axis
      xyz="0 0 0" />
    <limit
      lower="-0.2"
      upper="0"
      effort="0"
      velocity="0" />
  </joint>
  <link
    name="SuportMR1_Link">
    <inertial>
      <origin
        xyz="0.190240986234762 -0.167323573865871 -0.136245077283678"
        rpy="0 0 0" />
      <mass
        value="2.54893478703683E-14" />
      <inertia
        ixx="2.02436254768541E-17"
        ixy="1.34985144449705E-34"
        ixz="7.6274306503081E-33"
        iyy="1.9230003872193E-17"
        iyz="-4.43488387471056E-18"
        izz="6.65997704462131E-18" />
    </inertial>
    <visual>
      <origin
        xyz="0 0 0"
        rpy="0 0 0" />
      <geometry>
        <mesh
          filename="package://rUBotcoop_mecanum/meshes/SuportMR1_Link.STL" />
      </geometry>
      <material
        name="">
        <color
          rgba="0.792156862745098 0.819607843137255 0.933333333333333 1" />
      </material>
    </visual>
    <collision>
      <origin
        xyz="0 0 0"
        rpy="0 0 0" />
      <geometry>
        <mesh
          filename="package://rUBotcoop_mecanum/meshes/SuportMR1_Link.STL" />
      </geometry>
    </collision>
  </link>
  <joint
    name="joint_SuportMR1"
    type="fixed">
    <origin
      xyz="0 0 0"
      rpy="0 0 0" />
    <parent
      link="base_link" />
    <child
      link="SuportMR1_Link" />
    <axis
      xyz="0 0 0" />
  </joint>
  <link
    name="SuportML1_Link">
    <inertial>
      <origin
        xyz="0.190240986234762 0.127802835358702 -0.136245077283677"
        rpy="0 0 0" />
      <mass
        value="2.54893478703682E-14" />
      <inertia
        ixx="2.02436254768541E-17"
        ixy="-1.58935337858327E-33"
        ixz="3.93745200371624E-33"
        iyy="1.9230003872193E-17"
        iyz="4.43488387471057E-18"
        izz="6.65997704462131E-18" />
    </inertial>
    <visual>
      <origin
        xyz="0 0 0"
        rpy="0 0 0" />
      <geometry>
        <mesh
          filename="package://rUBotcoop_mecanum/meshes/SuportML1_Link.STL" />
      </geometry>
      <material
        name="">
        <color
          rgba="0.792156862745098 0.819607843137255 0.933333333333333 1" />
      </material>
    </visual>
    <collision>
      <origin
        xyz="0 0 0"
        rpy="0 0 0" />
      <geometry>
        <mesh
          filename="package://rUBotcoop_mecanum/meshes/SuportML1_Link.STL" />
      </geometry>
    </collision>
  </link>
  <joint
    name="joint_SuportML1"
    type="fixed">
    <origin
      xyz="0 0 0"
      rpy="0 0 0" />
    <parent
      link="base_link" />
    <child
      link="SuportML1_Link" />
    <axis
      xyz="0 0 0" />
  </joint>
  <link
    name="SuportMR2_Link">
    <inertial>
      <origin
        xyz="-0.133359013765239 -0.167323573865871 -0.136245077283678"
        rpy="0 0 0" />
      <mass
        value="2.54893478703683E-14" />
      <inertia
        ixx="2.02436254768542E-17"
        ixy="-5.29793030468644E-33"
        ixz="-1.68811615077954E-32"
        iyy="1.9230003872193E-17"
        iyz="-4.43488387471055E-18"
        izz="6.6599770446213E-18" />
    </inertial>
    <visual>
      <origin
        xyz="0 0 0"
        rpy="0 0 0" />
      <geometry>
        <mesh
          filename="package://rUBotcoop_mecanum/meshes/SuportMR2_Link.STL" />
      </geometry>
      <material
        name="">
        <color
          rgba="0.792156862745098 0.819607843137255 0.933333333333333 1" />
      </material>
    </visual>
    <collision>
      <origin
        xyz="0 0 0"
        rpy="0 0 0" />
      <geometry>
        <mesh
          filename="package://rUBotcoop_mecanum/meshes/SuportMR2_Link.STL" />
      </geometry>
    </collision>
  </link>
  <joint
    name="joint_SuportMR2"
    type="fixed">
    <origin
      xyz="0 0 0"
      rpy="0 0 0" />
    <parent
      link="base_link" />
    <child
      link="SuportMR2_Link" />
    <axis
      xyz="0 0 0" />
  </joint>
  <link
    name="SuportML2_Link">
    <inertial>
      <origin
        xyz="-0.133359013765239 0.127802835358702 -0.136245077283677"
        rpy="0 0 0" />
      <mass
        value="2.54893478703682E-14" />
      <inertia
        ixx="2.02436254768541E-17"
        ixy="-1.48266934258178E-32"
        ixz="3.06188261174757E-32"
        iyy="1.9230003872193E-17"
        iyz="4.43488387471057E-18"
        izz="6.65997704462132E-18" />
    </inertial>
    <visual>
      <origin
        xyz="0 0 0"
        rpy="0 0 0" />
      <geometry>
        <mesh
          filename="package://rUBotcoop_mecanum/meshes/SuportML2_Link.STL" />
      </geometry>
      <material
        name="">
        <color
          rgba="0.792156862745098 0.819607843137255 0.933333333333333 1" />
      </material>
    </visual>
    <collision>
      <origin
        xyz="0 0 0"
        rpy="0 0 0" />
      <geometry>
        <mesh
          filename="package://rUBotcoop_mecanum/meshes/SuportML2_Link.STL" />
      </geometry>
    </collision>
  </link>
  <joint
    name="joint_SuportML2"
    type="fixed">
    <origin
      xyz="0 0 0"
      rpy="0 0 0" />
    <parent
      link="base_link" />
    <child
      link="SuportML2_Link" />
    <axis
      xyz="0 0 0" />
  </joint>
  <link
    name="R1_Link">
    <inertial>
      <origin
        xyz="0.19024 -0.21509 -0.18093"
        rpy="0 0 0" />
      <mass
        value="0.38394" />
      <inertia
        ixx="0.0001602"
        ixy="-7.3492E-12"
        ixz="1.3026E-10"
        iyy="0.00023557"
        iyz="-4.8E-12"
        izz="0.0001602" />
    </inertial>
    <visual>
      <origin
        xyz="0 0 0"
        rpy="0 0 0" />
      <geometry>
        <mesh
          filename="package://rUBotcoop_mecanum/meshes/R1_Link.STL" />
      </geometry>
      <material
        name="">
        <color
          rgba="0.79216 0.81961 0.93333 1" />
      </material>
    </visual>
    <collision>
      <origin
        xyz="0 0 0"
        rpy="0 0 0" />
      <geometry>
        <mesh
          filename="package://rUBotcoop_mecanum/meshes/R1_Link.STL" />
      </geometry>
    </collision>
  </link>
  <joint
    name="joint_R1"
    type="continuous">
    <origin
      xyz="0 0 0"
      rpy="0 0 0" />
    <parent
      link="base_link" />
    <child
      link="R1_Link" />
    <axis
      xyz="0 1 0" />
  </joint>
  <link
    name="L1_Link">
    <inertial>
      <origin
        xyz="0.190240943143321 0.175566774257101 -0.180932674543495"
        rpy="0 0 0" />
      <mass
        value="0.383940518115187" />
      <inertia
        ixx="0.000160200198814806"
        ixy="-3.45253719252988E-11"
        ixz="-1.60009721033914E-10"
        iyy="0.000235568986288032"
        iyz="4.96443788890198E-11"
        izz="0.000160200317616536" />
    </inertial>
    <visual>
      <origin
        xyz="0 0 0"
        rpy="0 0 0" />
      <geometry>
        <mesh
          filename="package://rUBotcoop_mecanum/meshes/L1_Link.STL" />
      </geometry>
      <material
        name="">
        <color
          rgba="0.792156862745098 0.819607843137255 0.933333333333333 1" />
      </material>
    </visual>
    <collision>
      <origin
        xyz="0 0 0"
        rpy="0 0 0" />
      <geometry>
        <mesh
          filename="package://rUBotcoop_mecanum/meshes/L1_Link.STL" />
      </geometry>
    </collision>
  </link>
  <joint
    name="joint_L1"
    type="continuous">
    <origin
      xyz="0 0 0"
      rpy="0 0 0" />
    <parent
      link="base_link" />
    <child
      link="L1_Link" />
    <axis
      xyz="0 1 0" />
  </joint>
  <link
    name="R2_Link">
    <inertial>
      <origin
        xyz="-0.133358966564122 -0.215087513495667 -0.180932621623078"
        rpy="0 0 0" />
      <mass
        value="0.383940489023943" />
      <inertia
        ixx="0.000160200144686595"
        ixy="2.64443282999573E-11"
        ixz="-1.34249931824287E-10"
        iyy="0.000235568971072202"
        iyz="-5.43811018013371E-11"
        izz="0.000160200355480651" />
    </inertial>
    <visual>
      <origin
        xyz="0 0 0"
        rpy="0 0 0" />
      <geometry>
        <mesh
          filename="package://rUBotcoop_mecanum/meshes/R2_Link.STL" />
      </geometry>
      <material
        name="">
        <color
          rgba="0.792156862745098 0.819607843137255 0.933333333333333 1" />
      </material>
    </visual>
    <collision>
      <origin
        xyz="0 0 0"
        rpy="0 0 0" />
      <geometry>
        <mesh
          filename="package://rUBotcoop_mecanum/meshes/R2_Link.STL" />
      </geometry>
    </collision>
  </link>
  <joint
    name="joint_R2"
    type="continuous">
    <origin
      xyz="0 0 0"
      rpy="0 0 0" />
    <parent
      link="base_link" />
    <child
      link="R2_Link" />
    <axis
      xyz="0 1 0" />
  </joint>
  <link
    name="L2_Link">
    <inertial>
      <origin
        xyz="-0.133359013765297 0.175566946695439 -0.180932686457985"
        rpy="0 0 0" />
      <mass
        value="0.383942544876254" />
      <inertia
        ixx="0.000160200609592822"
        ixy="8.77755939197018E-12"
        ixz="7.38003881984372E-17"
        iyy="0.000235567297373846"
        iyz="1.32162987441133E-15"
        izz="0.000160200325120215" />
    </inertial>
    <visual>
      <origin
        xyz="0 0 0"
        rpy="0 0 0" />
      <geometry>
        <mesh
          filename="package://rUBotcoop_mecanum/meshes/L2_Link.STL" />
      </geometry>
      <material
        name="">
        <color
          rgba="0.792156862745098 0.819607843137255 0.933333333333333 1" />
      </material>
    </visual>
    <collision>
      <origin
        xyz="0 0 0"
        rpy="0 0 0" />
      <geometry>
        <mesh
          filename="package://rUBotcoop_mecanum/meshes/L2_Link.STL" />
      </geometry>
    </collision>
  </link>
  <joint
    name="joint_L2"
    type="continuous">
    <origin
      xyz="0 0 0"
      rpy="0 0 0" />
    <parent
      link="base_link" />
    <child
      link="L2_Link" />
    <axis
      xyz="0 1 0" />
  </joint>
  <link
    name="MR1_Link">
    <inertial>
      <origin
        xyz="0.190366281023609 -0.143706161605733 -0.174082729445397"
        rpy="0 0 0" />
      <mass
        value="0.0568898396886143" />
      <inertia
        ixx="2.16430504132729E-05"
        ixy="-1.5609549027946E-07"
        ixz="-7.2412664372835E-10"
        iyy="8.51339721047066E-06"
        iyz="-1.74927784904546E-07"
        izz="2.17113865023018E-05" />
    </inertial>
    <visual>
      <origin
        xyz="0 0 0"
        rpy="0 0 0" />
      <geometry>
        <mesh
          filename="package://rUBotcoop_mecanum/meshes/MR1_Link.STL" />
      </geometry>
      <material
        name="">
        <color
          rgba="0.792156862745098 0.819607843137255 0.933333333333333 1" />
      </material>
    </visual>
    <collision>
      <origin
        xyz="0 0 0"
        rpy="0 0 0" />
      <geometry>
        <mesh
          filename="package://rUBotcoop_mecanum/meshes/MR1_Link.STL" />
      </geometry>
    </collision>
  </link>
  <joint
    name="joint_MR1"
    type="fixed">
    <origin
      xyz="0 0 0"
      rpy="0 0 0" />
    <parent
      link="base_link" />
    <child
      link="MR1_Link" />
    <axis
      xyz="0 0 0" />
  </joint>
  <link
    name="ML1_Link">
    <inertial>
      <origin
        xyz="0.190115691445914 0.104185423098564 -0.174082729445396"
        rpy="0 0 0" />
      <mass
        value="0.0568898396886143" />
      <inertia
        ixx="2.16430504132729E-05"
        ixy="-1.56095490279455E-07"
        ixz="7.24126643729239E-10"
        iyy="8.51339721047066E-06"
        iyz="1.74927784904539E-07"
        izz="2.17113865023018E-05" />
    </inertial>
    <visual>
      <origin
        xyz="0 0 0"
        rpy="0 0 0" />
      <geometry>
        <mesh
          filename="package://rUBotcoop_mecanum/meshes/ML1_Link.STL" />
      </geometry>
      <material
        name="">
        <color
          rgba="0.792156862745098 0.819607843137255 0.933333333333333 1" />
      </material>
    </visual>
    <collision>
      <origin
        xyz="0 0 0"
        rpy="0 0 0" />
      <geometry>
        <mesh
          filename="package://rUBotcoop_mecanum/meshes/ML1_Link.STL" />
      </geometry>
    </collision>
  </link>
  <joint
    name="joint_ML1"
    type="fixed">
    <origin
      xyz="0 0 0"
      rpy="0 0 0" />
    <parent
      link="base_link" />
    <child
      link="ML1_Link" />
    <axis
      xyz="0 0 0" />
  </joint>
  <link
    name="MR2_Link">
    <inertial>
      <origin
        xyz="-0.133233718976391 -0.143706161605733 -0.174082729445397"
        rpy="0 0 0" />
      <mass
        value="0.0568898396886143" />
      <inertia
        ixx="2.16430504132729E-05"
        ixy="-1.56095490279478E-07"
        ixz="-7.24126643728311E-10"
        iyy="8.51339721047067E-06"
        iyz="-1.74927784904551E-07"
        izz="2.17113865023018E-05" />
    </inertial>
    <visual>
      <origin
        xyz="0 0 0"
        rpy="0 0 0" />
      <geometry>
        <mesh
          filename="package://rUBotcoop_mecanum/meshes/MR2_Link.STL" />
      </geometry>
      <material
        name="">
        <color
          rgba="0.792156862745098 0.819607843137255 0.933333333333333 1" />
      </material>
    </visual>
    <collision>
      <origin
        xyz="0 0 0"
        rpy="0 0 0" />
      <geometry>
        <mesh
          filename="package://rUBotcoop_mecanum/meshes/MR2_Link.STL" />
      </geometry>
    </collision>
  </link>
  <joint
    name="joint_MR2"
    type="fixed">
    <origin
      xyz="0 0 0"
      rpy="0 0 0" />
    <parent
      link="base_link" />
    <child
      link="MR2_Link" />
    <axis
      xyz="0 0 0" />
  </joint>
  <link
    name="ML2_Link">
    <inertial>
      <origin
        xyz="-0.133484308554086 0.104185423098564 -0.174082729445396"
        rpy="0 0 0" />
      <mass
        value="0.0568898396886143" />
      <inertia
        ixx="2.16430504132728E-05"
        ixy="-1.56095490279473E-07"
        ixz="7.24126643728921E-10"
        iyy="8.51339721047066E-06"
        iyz="1.74927784904534E-07"
        izz="2.17113865023018E-05" />
    </inertial>
    <visual>
      <origin
        xyz="0 0 0"
        rpy="0 0 0" />
      <geometry>
        <mesh
          filename="package://rUBotcoop_mecanum/meshes/ML2_Link.STL" />
      </geometry>
      <material
        name="">
        <color
          rgba="0.792156862745098 0.819607843137255 0.933333333333333 1" />
      </material>
    </visual>
    <collision>
      <origin
        xyz="0 0 0"
        rpy="0 0 0" />
      <geometry>
        <mesh
          filename="package://rUBotcoop_mecanum/meshes/ML2_Link.STL" />
      </geometry>
    </collision>
  </link>
  <joint
    name="joint_ML2"
    type="fixed">
    <origin
      xyz="0 0 0"
      rpy="0 0 0" />
    <parent
      link="base_link" />
    <child
      link="ML2_Link" />
    <axis
      xyz="0 0 0" />
  </joint>
  <link
    name="SuportCentre1_Link">
    <inertial>
      <origin
        xyz="0.190240986234762 -0.0197603692535851 -0.123144960869108"
        rpy="0 0 0" />
      <mass
        value="0.0669507766214093" />
      <inertia
        ixx="0.000378535151720878"
        ixy="-1.05872032699741E-11"
        ixz="-9.32038950909216E-20"
        iyy="3.15577343168385E-05"
        iyz="-3.99908044191436E-18"
        izz="0.000362568392195281" />
    </inertial>
    <visual>
      <origin
        xyz="0 0 0"
        rpy="0 0 0" />
      <geometry>
        <mesh
          filename="package://rUBotcoop_mecanum/meshes/SuportCentre1_Link.STL" />
      </geometry>
      <material
        name="">
        <color
          rgba="0.792156862745098 0.819607843137255 0.933333333333333 1" />
      </material>
    </visual>
    <collision>
      <origin
        xyz="0 0 0"
        rpy="0 0 0" />
      <geometry>
        <mesh
          filename="package://rUBotcoop_mecanum/meshes/SuportCentre1_Link.STL" />
      </geometry>
    </collision>
  </link>
  <joint
    name="joint_SuportCentre1"
    type="fixed">
    <origin
      xyz="0 0 0"
      rpy="0 0 0" />
    <parent
      link="base_link" />
    <child
      link="SuportCentre1_Link" />
    <axis
      xyz="0 0 0" />
  </joint>
  <link
    name="SuportCentre2_Link">
    <inertial>
      <origin
        xyz="-0.133359013765239 -0.0197603692535846 -0.123144960869108"
        rpy="0 0 0" />
      <mass
        value="0.0669507766214103" />
      <inertia
        ixx="0.000378535151720885"
        ixy="-1.05872033500054E-11"
        ixz="-7.19182837784651E-20"
        iyy="3.15577343168399E-05"
        iyz="-2.97637255379468E-18"
        izz="0.000362568392195286" />
    </inertial>
    <visual>
      <origin
        xyz="0 0 0"
        rpy="0 0 0" />
      <geometry>
        <mesh
          filename="package://rUBotcoop_mecanum/meshes/SuportCentre2_Link.STL" />
      </geometry>
      <material
        name="">
        <color
          rgba="0.792156862745098 0.819607843137255 0.933333333333333 1" />
      </material>
    </visual>
    <collision>
      <origin
        xyz="0 0 0"
        rpy="0 0 0" />
      <geometry>
        <mesh
          filename="package://rUBotcoop_mecanum/meshes/SuportCentre2_Link.STL" />
      </geometry>
    </collision>
  </link>
  <joint
    name="joint_SuportCentre2"
    type="fixed">
    <origin
      xyz="0 0 0"
      rpy="0 0 0" />
    <parent
      link="base_link" />
    <child
      link="SuportCentre2_Link" />
    <axis
      xyz="0 0 0" />
  </joint>
  <link
    name="SuportLidar_Link">
    <inertial>
      <origin
        xyz="0.227558314004439 -0.0197601971689057 -0.0652431702877647"
        rpy="0 0 0" />
      <mass
        value="0.0608283980591504" />
      <inertia
        ixx="4.90100368938017E-05"
        ixy="1.11693718998757E-09"
        ixz="3.84054517720639E-07"
        iyy="9.70408126614275E-05"
        iyz="5.90756790540856E-11"
        izz="0.000122668352099749" />
    </inertial>
    <visual>
      <origin
        xyz="0 0 0"
        rpy="0 0 0" />
      <geometry>
        <mesh
          filename="package://rUBotcoop_mecanum/meshes/SuportLidar_Link.STL" />
      </geometry>
      <material
        name="">
        <color
          rgba="1 1 1 1" />
      </material>
    </visual>
    <collision>
      <origin
        xyz="0 0 0"
        rpy="0 0 0" />
      <geometry>
        <mesh
          filename="package://rUBotcoop_mecanum/meshes/SuportLidar_Link.STL" />
      </geometry>
    </collision>
  </link>
  <joint
    name="joint_SuportLidar"
    type="fixed">
    <origin
      xyz="0 0 0"
      rpy="0 0 0" />
    <parent
      link="base_link" />
    <child
      link="SuportLidar_Link" />
    <axis
      xyz="0 0 0" />
  </joint>
  <link
    name="Lidar_Link">
    <inertial>
      <origin
        xyz="0.241002840357545 -0.019671965350921 -0.0116798073175813"
        rpy="0 0 0" />
      <mass
        value="0.134107312465981" />
      <inertia
        ixx="4.5528108756831E-05"
        ixy="-3.94767799937156E-10"
        ixz="6.7406179850395E-13"
        iyy="5.75373075830395E-05"
        iyz="-5.69541050115237E-11"
        izz="9.32616751986301E-05" />
    </inertial>
    <visual>
      <origin
        xyz="0 0 0"
        rpy="0 0 0" />
      <geometry>
        <mesh
          filename="package://rUBotcoop_mecanum/meshes/Lidar_Link.STL" />
      </geometry>
      <material
        name="">
        <color
          rgba="0.792156862745098 0.819607843137255 0.933333333333333 1" />
      </material>
    </visual>
    <collision>
      <origin
        xyz="0 0 0"
        rpy="0 0 0" />
      <geometry>
        <mesh
          filename="package://rUBotcoop_mecanum/meshes/Lidar_Link.STL" />
      </geometry>
    </collision>
  </link>
  <joint
    name="joint_Lidar"
    type="fixed">
    <origin
      xyz="0 0 0"
      rpy="0 0 0" />
    <parent
      link="base_link" />
    <child
      link="Lidar_Link" />
    <axis
      xyz="0 0 0" />
  </joint>
  <link
    name="PlataformaSup_Link">
    <inertial>
      <origin
        xyz="0.0206420247116084 -0.0197603692535851 0.0496890169860071"
        rpy="0 0 0" />
      <mass
        value="2.36859288871575" />
      <inertia
        ixx="0.0332000223558737"
        ixy="1.60844506157554E-17"
        ixz="-0.00124729826883521"
        iyy="0.051360416968501"
        iyz="-2.78180962234125E-16"
        izz="0.0791503234773247" />
    </inertial>
    <visual>
      <origin
        xyz="0 0 0"
        rpy="0 0 0" />
      <geometry>
        <mesh
          filename="package://rUBotcoop_mecanum/meshes/PlataformaSup_Link.STL" />
      </geometry>
      <material
        name="">
        <color
          rgba="0.792156862745098 0.819607843137255 0.933333333333333 1" />
      </material>
    </visual>
    <collision>
      <origin
        xyz="0 0 0"
        rpy="0 0 0" />
      <geometry>
        <mesh
          filename="package://rUBotcoop_mecanum/meshes/PlataformaSup_Link.STL" />
      </geometry>
    </collision>
  </link>
  <joint
    name="joint_PlataformaSup"
    type="fixed">
    <origin
      xyz="0 0 0"
      rpy="0 0 0" />
    <parent
      link="base_link" />
    <child
      link="PlataformaSup_Link" />
    <axis
      xyz="0 0 0" />
  </joint>
  <link
    name="AttachR1_Link">
    <inertial>
      <origin
        xyz="0.190240986234762 -0.211010369253584 -0.180937426773138"
        rpy="0 0 0" />
      <mass
        value="0.0487809346941653" />
      <inertia
        ixx="1.799861613752E-05"
        ixy="1.05879118406788E-24"
        ixz="-3.68876998292282E-25"
        iyy="6.72811270213157E-06"
        iyz="-4.11901139709596E-20"
        izz="1.79980573811107E-05" />
    </inertial>
    <visual>
      <origin
        xyz="0 0 0"
        rpy="0 0 0" />
      <geometry>
        <mesh
          filename="package://rUBotcoop_mecanum/meshes/AttachR1_Link.STL" />
      </geometry>
      <material
        name="">
        <color
          rgba="0.2 0.2 0.2 1" />
      </material>
    </visual>
    <collision>
      <origin
        xyz="0 0 0"
        rpy="0 0 0" />
      <geometry>
        <mesh
          filename="package://rUBotcoop_mecanum/meshes/AttachR1_Link.STL" />
      </geometry>
    </collision>
  </link>
  <joint
    name="joint_AttachR1"
    type="fixed">
    <origin
      xyz="0 0 0"
      rpy="0 0 0" />
    <parent
      link="base_link" />
    <child
      link="AttachR1_Link" />
    <axis
      xyz="0 0 0" />
  </joint>
  <link
    name="AttachL1_Link">
    <inertial>
      <origin
        xyz="0.190240986234761 0.171489630746416 -0.180937426773137"
        rpy="0 0 0" />
      <mass
        value="0.0487809346941654" />
      <inertia
        ixx="1.799861613752E-05"
        ixy="-4.37173637705101E-22"
        ixz="-1.72809644020263E-24"
        iyy="6.72811270213157E-06"
        iyz="-4.6488719961839E-22"
        izz="1.79980573811108E-05" />
    </inertial>
    <visual>
      <origin
        xyz="0 0 0"
        rpy="0 0 0" />
      <geometry>
        <mesh
          filename="package://rUBotcoop_mecanum/meshes/AttachL1_Link.STL" />
      </geometry>
      <material
        name="">
        <color
          rgba="0.2 0.2 0.2 1" />
      </material>
    </visual>
    <collision>
      <origin
        xyz="0 0 0"
        rpy="0 0 0" />
      <geometry>
        <mesh
          filename="package://rUBotcoop_mecanum/meshes/AttachL1_Link.STL" />
      </geometry>
    </collision>
  </link>
  <joint
    name="joint_AttachL1"
    type="fixed">
    <origin
      xyz="0 0 0"
      rpy="0 0 0" />
    <parent
      link="base_link" />
    <child
      link="AttachL1_Link" />
    <axis
      xyz="0 0 0" />
  </joint>
  <link
    name="AttachR2_Link">
    <inertial>
      <origin
        xyz="-0.133359013765239 -0.211010369253584 -0.180937426773138"
        rpy="0 0 0" />
      <mass
        value="0.0487809346941653" />
      <inertia
        ixx="1.799861613752E-05"
        ixy="1.05879118406792E-24"
        ixz="-2.62185345173502E-25"
        iyy="6.72811270213157E-06"
        iyz="-1.5500463362193E-20"
        izz="1.79980573811107E-05" />
    </inertial>
    <visual>
      <origin
        xyz="0 0 0"
        rpy="0 0 0" />
      <geometry>
        <mesh
          filename="package://rUBotcoop_mecanum/meshes/AttachR2_Link.STL" />
      </geometry>
      <material
        name="">
        <color
          rgba="0.2 0.2 0.2 1" />
      </material>
    </visual>
    <collision>
      <origin
        xyz="0 0 0"
        rpy="0 0 0" />
      <geometry>
        <mesh
          filename="package://rUBotcoop_mecanum/meshes/AttachR2_Link.STL" />
      </geometry>
    </collision>
  </link>
  <joint
    name="joint_AttachR2"
    type="fixed">
    <origin
      xyz="0 0 0"
      rpy="0 0 0" />
    <parent
      link="base_link" />
    <child
      link="AttachR2_Link" />
    <axis
      xyz="0 0 0" />
  </joint>
  <link
    name="AttachL2_Link">
    <inertial>
      <origin
        xyz="0 0 0"
        rpy="0 0 0" />
      <mass
        value="0" />
      <inertia
        ixx="0"
        ixy="0"
        ixz="0"
        iyy="0"
        iyz="0"
        izz="0" />
    </inertial>
    <visual>
      <origin
        xyz="0 0 0"
        rpy="0 0 0" />
      <geometry>
        <mesh
          filename="package://rUBotcoop_mecanum/meshes/AttachL2_Link.STL" />
      </geometry>
      <material
        name="">
        <color
          rgba="1 1 1 1" />
      </material>
    </visual>
    <collision>
      <origin
        xyz="0 0 0"
        rpy="0 0 0" />
      <geometry>
        <mesh
          filename="package://rUBotcoop_mecanum/meshes/AttachL2_Link.STL" />
      </geometry>
    </collision>
  </link>
  <joint
    name="joint_AttachL2"
    type="fixed">
    <origin
      xyz="0 0 0"
      rpy="0 0 0" />
    <parent
      link="base_link" />
    <child
      link="AttachL2_Link" />
    <axis
      xyz="0 0 0" />
  </joint>
</robot>